Workbook

Sheet Cleaned_data_read_only
A1: Area of Residence | B1: Total Medicare Advantage Part A Enrollees² | C1: Total Persons With Utilization | D1: Utilization Rate | E1: Total Discharges | F1: Discharges Per 1,000 Medicare Advantage Part A Enrollees | G1: Discharges per 1,000 Persons With Utilization | H1: Total Discharges Beginning with Emergency Room Visit³ | I1: Total Days of Care | J1: Total Days Per 1,000 Medicare Advantage Part A Enrollees | K1: Total Days Per Person With Utilization | L1: Total Days Per Discharge | M1: Discharged Dead⁴
A2: Alabama | B2: 588194 | C2: 88688 | D2: =MDCR_INPT_HOSP_MA_7_CPS_13UMI[[#This Row],[Total Persons With Utilization]]/MDCR_INPT_HOSP_MA_7_CPS_13UMI[[#This Row],[Total Medicare Advantage Part A Enrollees²]]*100 -> 15.078018 | E2: 132442 | F2: 225 | G2: 1493 | H2: 102393 | I2: 874618 | J2: 1486.96 | K2: 9.86 | L2: 6.6037813 | M2: 4923
A3: Alaska | B3: 2633 | C3: 293 | D3: =MDCR_INPT_HOSP_MA_7_CPS_13UMI[[#This Row],[Total Persons With Utilization]]/MDCR_INPT_HOSP_MA_7_CPS_13UMI[[#This Row],[Total Medicare Advantage Part A Enrollees²]]*100 -> 11.127991 | E3: 441 | F3: 168 | G3: 1505 | H3: 374 | I3: 2955 | J3: 1122.47 | K3: 10.09 | L3: 6.7006803 | M3: 19
A4: Arizona | B4: 676493 | C4: 89376 | D4: =MDCR_INPT_HOSP_MA_7_CPS_13UMI[[#This Row],[Total Persons With Utilization]]/MDCR_INPT_HOSP_MA_7_CPS_13UMI[[#This Row],[Total Medicare Advantage Part A Enrollees²]]*100 -> 13.211667 | E4: 132170 | F4: 195 | G4: 1479 | H4: 107025 | I4: 771735 | J4: 1140.79 | K4: 8.63 | L4: 5.8389574 | M4: 5563
A5: Arkansas | B5: 247249 | C5: 38166 | D5: =MDCR_INPT_HOSP_MA_7_CPS_13UMI[[#This Row],[Total Persons With Utilization]]/MDCR_INPT_HOSP_MA_7_CPS_13UMI[[#This Row],[Total Medicare Advantage Part A Enrollees²]]*100 -> 15.436261 | E5: 58207 | F5: 235 | G5: 1525 | H5: 44696 | I5: 334879 | J5: 1354.42 | K5: 8.77 | L5: 5.7532427 | M5: 1998
A6: California | B6: 3203822 | C6: 355399 | D6: =MDCR_INPT_HOSP_MA_7_CPS_13UMI[[#This Row],[Total Persons With Utilization]]/MDCR_INPT_HOSP_MA_7_CPS_13UMI[[#This Row],[Total Medicare Advantage Part A Enrollees²]]*100 -> 11.09297 | E6: 517290 | F6: 161 | G6: 1456 | H6: 429005 | I6: 2940860 | J6: 917.92 | K6: 8.27 | L6: 5.6851283 | M6: 24077
A7: Colorado | B7: 474146 | C7: 55488 | D7: =MDCR_INPT_HOSP_MA_7_CPS_13UMI[[#This Row],[Total Persons With Utilization]]/MDCR_INPT_HOSP_MA_7_CPS_13UMI[[#This Row],[Total Medicare Advantage Part A Enrollees²]]*100 -> 11.702724 | E7: 77668 | F7: 164 | G7: 1400 | H7: 60892 | I7: 432416 | J7: 911.99 | K7: 7.79 | L7: 5.5674924 | M7: 3076
A8: Connecticut | B8: 364421 | C8: 47625 | D8: =MDCR_INPT_HOSP_MA_7_CPS_13UMI[[#This Row],[Total Persons With Utilization]]/MDCR_INPT_HOSP_MA_7_CPS_13UMI[[#This Row],[Total Medicare Advantage Part A Enrollees²]]*100 -> 13.068676 | E8: 71924 | F8: 197 | G8: 1510 | H8: 58991 | I8: 440901 | J8: 1209.87 | K8: 9.26 | L8: 6.1300957 | M8: 2866
A9: Delaware | B9: 61979 | C9: 8693 | D9: =MDCR_INPT_HOSP_MA_7_CPS_13UMI[[#This Row],[Total Persons With Utilization]]/MDCR_INPT_HOSP_MA_7_CPS_13UMI[[#This Row],[Total Medicare Advantage Part A Enrollees²]]*100 -> 14.025718 | E9: 13079 | F9: 211 | G9: 1505 | H9: 11281 | I9: 99859 | J9: 1611.17 | K9: 11.49 | L9: 7.6350638 | M9: 511
A10: District of Columbia | B10: 26530 | C10: 4297 | D10: =MDCR_INPT_HOSP_MA_7_CPS_13UMI[[#This Row],[Total Persons With Utilization]]/MDCR_INPT_HOSP_MA_7_CPS_13UMI[[#This Row],[Total Medicare Advantage Part A Enrollees²]]*100 -> 16.196758 | E10: 7119 | F10: 268 | G10: 1657 | H10: 6231 | I10: 62321 | J10: 2349.07 | K10: 14.5 | L10: 8.754179 | M10: 385
A11: Florida | B11: 2600257 | C11: 367752 | D11: =MDCR_INPT_HOSP_MA_7_CPS_13UMI[[#This Row],[Total Persons With Utilization]]/MDCR_INPT_HOSP_MA_7_CPS_13UMI[[#This Row],[Total Medicare Advantage Part A Enrollees²]]*100 -> 14.14291 | E11: 562993 | F11: 217 | G11: 1531 | H11: 467699 | I11: 3328274 | J11: 1279.98 | K11: 9.05 | L11: 5.9117502 | M11: 14817
A12: Georgia | B12: 931049 | C12: 134819 | D12: =MDCR_INPT_HOSP_MA_7_CPS_13UMI[[#This Row],[Total Persons With Utilization]]/MDCR_INPT_HOSP_MA_7_CPS_13UMI[[#This Row],[Total Medicare Advantage Part A Enrollees²]]*100 -> 14.480333 | E12: 207197 | F12: 223 | G12: 1537 | H12: 170280 | I12: 1391255 | J12: 1494.29 | K12: 10.32 | L12: 6.7146484 | M12: 7458
A13: Hawaii | B13: 151349 | C13: 16907 | D13: =MDCR_INPT_HOSP_MA_7_CPS_13UMI[[#This Row],[Total Persons With Utilization]]/MDCR_INPT_HOSP_MA_7_CPS_13UMI[[#This Row],[Total Medicare Advantage Part A Enrollees²]]*100 -> 11.17087 | E13: 24086 | F13: 159 | G13: 1425 | H13: 20959 | I13: 189384 | J13: 1251.31 | K13: 11.2 | L13: 7.8628249 | M13: 1207
... A53: Wyoming | B53: 10264 | C53: 1185 | D53: =MDCR_INPT_HOSP_MA_7_CPS_13UMI[[#This Row],[Total Persons With Utilization]]/MDCR_INPT_HOSP_MA_7_CPS_13UMI[[#This Row],[Total Medicare Advantage Part A Enrollees²]]*100 -> 11.545207 | E53: 1660 | F53: 162 | G53: 1401 | H53: 1248 | I53: 9232 | J53: 899.42 | K53: 7.79 | L53: 5.5614458 | M53: 66

Sheet LOS
A3: Row Labels | B3: Discharges Per 1,000 Medicare Advantage Part A Enrollees | C3: LOS
A4: Alabama | B4: 225 | C4: 6.6037813
A5: Alaska | B5: 168 | C5: 6.7006803
A6: Arizona | B6: 195 | C6: 5.8389574
A7: Arkansas | B7: 235 | C7: 5.7532427
A8: California | B8: 161 | C8: 5.6851283
A9: Colorado | B9: 164 | C9: 5.5674924
A10: Connecticut | B10: 197 | C10: 6.1300957
A11: Delaware | B11: 211 | C11: 7.6350638
A12: District of Columbia | B12: 268 | C12: 8.754179
A13: Florida | B13: 217 | C13: 5.9117502
A14: Georgia | B14: 223 | C14: 6.7146484
A15: Hawaii | B15: 159 | C15: 7.8628249
... A56: Grand Total | B56: 9803 | C56: 6.1277113

Sheet LOS1
A1: States | B1: Total Discharges | C1: Total Days of Care | D1: Discharges Per 1,000 Medicare Advantage Part A Enrollees | E1: LOS | F1: Quadrant
A2: Alabama | B2: 132442 | C2: 874618 | D2: 225 | E2: 6.6037813 | F2: =IF(AND(D2>188,E2>6.3),"System Pressure",IF(AND(D2<188,E2>6.3),"Inefficient",IF(AND(D2<188,E2<6.3),"Underused but Efficient","Efficient / High Turnover"))) -> System Pressure
A3: Alaska | B3: 441 | C3: 2955 | D3: 168 | E3: 6.7006803 | F3: =IF(AND(D3>188,E3>6.3),"System Pressure",IF(AND(D3<188,E3>6.3),"Inefficient",IF(AND(D3<188,E3<6.3),"Underused but Efficient","Efficient / High Turnover"))) -> Inefficient
A4: Arizona | B4: 132170 | C4: 771735 | D4: 195 | E4: 5.8389574 | F4: =IF(AND(D4>188,E4>6.3),"System Pressure",IF(AND(D4<188,E4>6.3),"Inefficient",IF(AND(D4<188,E4<6.3),"Underused but Efficient","Efficient / High Turnover"))) -> Efficient / High Turnover
A5: Arkansas | B5: 58207 | C5: 334879 | D5: 235 | E5: 5.7532427 | F5: =IF(AND(D5>188,E5>6.3),"System Pressure",IF(AND(D5<188,E5>6.3),"Inefficient",IF(AND(D5<188,E5<6.3),"Underused but Efficient","Efficient / High Turnover"))) -> Efficient / High Turnover
A6: California | B6: 517290 | C6: 2940860 | D6: 161 | E6: 5.6851283 | F6: =IF(AND(D6>188,E6>6.3),"System Pressure",IF(AND(D6<188,E6>6.3),"Inefficient",IF(AND(D6<188,E6<6.3),"Underused but Efficient","Efficient / High Turnover"))) -> Underused but Efficient
A7: Colorado | B7: 77668 | C7: 432416 | D7: 164 | E7: 5.5674924 | F7: =IF(AND(D7>188,E7>6.3),"System Pressure",IF(AND(D7<188,E7>6.3),"Inefficient",IF(AND(D7<188,E7<6.3),"Underused but Efficient","Efficient / High Turnover"))) -> Underused but Efficient
A8: Connecticut | B8: 71924 | C8: 440901 | D8: 197 | E8: 6.1300957 | F8: =IF(AND(D8>188,E8>6.3),"System Pressure",IF(AND(D8<188,E8>6.3),"Inefficient",IF(AND(D8<188,E8<6.3),"Underused but Efficient","Efficient / High Turnover"))) -> Efficient / High Turnover
A9: Delaware | B9: 13079 | C9: 99859 | D9: 211 | E9: 7.6350638 | F9: =IF(AND(D9>188,E9>6.3),"System Pressure",IF(AND(D9<188,E9>6.3),"Inefficient",IF(AND(D9<188,E9<6.3),"Underused but Efficient","Efficient / High Turnover"))) -> System Pressure
A10: District of Columbia | B10: 7119 | C10: 62321 | D10: 268 | E10: 8.754179 | F10: =IF(AND(D10>188,E10>6.3),"System Pressure",IF(AND(D10<188,E10>6.3),"Inefficient",IF(AND(D10<188,E10<6.3),"Underused but Efficient","Efficient / High Turnover"))) -> System Pressure
A11: Florida | B11: 562993 | C11: 3328274 | D11: 217 | E11: 5.9117502 | F11: =IF(AND(D11>188,E11>6.3),"System Pressure",IF(AND(D11<188,E11>6.3),"Inefficient",IF(AND(D11<188,E11<6.3),"Underused but Efficient","Efficient / High Turnover"))) -> Efficient / High Turnover
A12: Georgia | B12: 207197 | C12: 1391255 | D12: 223 | E12: 6.7146484 | F12: =IF(AND(D12>188,E12>6.3),"System Pressure",IF(AND(D12<188,E12>6.3),"Inefficient",IF(AND(D12<188,E12<6.3),"Underused but Efficient","Efficient / High Turnover"))) -> System Pressure
A13: Hawaii | B13: 24086 | C13: 189384 | D13: 159 | E13: 7.8628249 | F13: =IF(AND(D13>188,E13>6.3),"System Pressure",IF(AND(D13<188,E13>6.3),"Inefficient",IF(AND(D13<188,E13<6.3),"Underused but Efficient","Efficient / High Turnover"))) -> Inefficient
... A23: Massachusetts | B23: 100035 | C23: 654517 | D23: 228 | E23: 6.54288 | F23: =IF(AND(D23>188,E23>6.3),"System Pressure",IF(AND(D23<188,E23>6.3),"Inefficient",IF(AND(D23<188,E23<6.3),"Underused but Efficient","Efficient / High Turnover"))) -> System Pressure
A24: Michigan | B24: 247920 | C24: 1521371 | D24: 206 | E24: 6.13654 | F24: =IF(AND(D24>188,E24>6.3),"System Pressure",IF(AND(D24<188,E24>6.3),"Inefficient",IF(AND(D24<188,E24<6.3),"Underused but Efficient","Efficient / High Turnover"))) -> Efficient / High Turnover | I24: Discharges | J24: LOS | L24: Average LOS
A25: Minnesota | B25: 87122 | C25: 506524 | D25: 145 | E25: 5.813962 | F25: =IF(AND(D25>188,E25>6.3),"System Pressure",IF(AND(D25<188,E25>6.3),"Inefficient",IF(AND(D25<188,E25<6.3),"Underused but Efficient","Efficient / High Turnover"))) -> Underused but Efficient | I25: 188.5 | J25: 0 | L25: 60 | M25: =AVERAGE(E2:E52) -> 6.3079312
A26: Mississippi | B26: 46983 | C26: 307660 | D26: 216 | E26: 6.548326 | F26: =IF(AND(D26>188,E26>6.3),"System Pressure",IF(AND(D26<188,E26>6.3),"Inefficient",IF(AND(D26<188,E26<6.3),"Underused but Efficient","Efficient / High Turnover"))) -> System Pressure | I26: 188.5 | J26: 10 | L26: 290 | M26: =AVERAGE(E2:E52) -> 6.3079312
A27: Missouri | B27: 141333 | C27: 814817 | D27: 232 | E27: 5.7652282 | F27: =IF(AND(D27>188,E27>6.3),"System Pressure",IF(AND(D27<188,E27>6.3),"Inefficient",IF(AND(D27<188,E27<6.3),"Underused but Efficient","Efficient / High Turnover"))) -> Efficient / High Turnover
A28: Montana | B28: 8705 | C28: 54161 | D28: 137 | E28: 6.2218265 | F28: =IF(AND(D28>188,E28>6.3),"System Pressure",IF(AND(D28<188,E28>6.3),"Inefficient",IF(AND(D28<188,E28<6.3),"Underused but Efficient","Efficient / High Turnover"))) -> Underused but Efficient
A29: Nebraska | B29: 17676 | C29: 113153 | D29: 168 | E29: 6.4015049 | F29: =IF(AND(D29>188,E29>6.3),"System Pressure",IF(AND(D29<188,E29>6.3),"Inefficient",IF(AND(D29<188,E29<6.3),"Underused but Efficient","Efficient / High Turnover"))) -> Inefficient | I29: ="System Pressure (" & COUNTA(I30:I42) & ")" -> System Pressure (13) | J29: ="High Turnover (" & COUNTA(J30:J46) & ")" -> High Turnover (17) | K29: ="Underused but Efficient (" & COUNTA(K30:K41) & ")" -> Underused but Efficient (11) | L29: ="Inefficient (" & COUNTA(L30:L38) & ")" -> Inefficient (9)
A30: Nevada | B30: 57568 | C30: 356465 | D30: 216 | E30: 6.1920685 | F30: =IF(AND(D30>188,E30>6.3),"System Pressure",IF(AND(D30<188,E30>6.3),"Inefficient",IF(AND(D30<188,E30<6.3),"Underused but Efficient","Efficient / High Turnover"))) -> Efficient / High Turnover | I30: {=_xlfn._xlws.SORT(_xlfn._xlws.FILTER($A$2:$A$52, $F$2:$F$52="System Pressure"))} -> Alabama | J30: {=_xlfn._xlws.SORT(_xlfn._xlws.FILTER($A$2:$A$52, $F$2:$F$52="Efficient / High Turnover"))} -> Arizona | K30: {=_xlfn._xlws.SORT(_xlfn._xlws.FILTER($A$2:$A$52, $F$2:$F$52="Underused but Efficient"))} -> California | L30: {=_xlfn._xlws.SORT(_xlfn._xlws.FILTER($A$2:$A$52, $F$2:$F$52="Inefficient"))} -> Alaska
A31: New Hampshire | B31: 14597 | C31: 99528 | D31: 153 | E31: 6.8183873 | F31: =IF(AND(D31>188,E31>6.3),"System Pressure",IF(AND(D31<188,E31>6.3),"Inefficient",IF(AND(D31<188,E31<6.3),"Underused but Efficient","Efficient / High Turnover"))) -> Inefficient | I31: Delaware | J31: Arkansas | K31: Colorado | L31: Hawaii
A32: New Jersey | B32: 143738 | C32: 887058 | D32: 230 | E32: 6.1713534 | F32: =IF(AND(D32>188,E32>6.3),"System Pressure",IF(AND(D32<188,E32>6.3),"Inefficient",IF(AND(D32<188,E32<6.3),"Underused but Efficient","Efficient / High Turnover"))) -> Efficient / High Turnover | I32: District of Columbia | J32: Connecticut | K32: Idaho | L32: Maine
A33: New Mexico | B33: 33947 | C33: 201889 | D33: 166 | E33: 5.9471824 | F33: =IF(AND(D33>188,E33>6.3),"System Pressure",IF(AND(D33<188,E33>6.3),"Inefficient",IF(AND(D33<188,E33<6.3),"Underused but Efficient","Efficient / High Turnover"))) -> Underused but Efficient | I33: Georgia | J33: Florida | K33: Iowa | L33: Nebraska
A34: New York | B34: 383219 | C34: 2596405 | D34: 211 | E34: 6.7752512 | F34: =IF(AND(D34>188,E34>6.3),"System Pressure",IF(AND(D34<188,E34>6.3),"Inefficient",IF(AND(D34<188,E34<6.3),"Underused but Efficient","Efficient / High Turnover"))) -> System Pressure | I34: Kentucky | J34: Illinois | K34: Minnesota | L34: New Hampshire
A35: North Carolina | B35: 199504 | C35: 1276274 | D35: 193 | E35: 6.3972351 | F35: =IF(AND(D35>188,E35>6.3),"System Pressure",IF(AND(D35<188,E35>6.3),"Inefficient",IF(AND(D35<188,E35<6.3),"Underused but Efficient","Efficient / High Turnover"))) -> System Pressure | I35: Maryland | J35: Indiana | K35: Montana | L35: Oregon
A36: North Dakota | B36: 2653 | C36: 16091 | D36: 70 | E36: 6.0652092 | F36: =IF(AND(D36>188,E36>6.3),"System Pressure",IF(AND(D36<188,E36>6.3),"Inefficient",IF(AND(D36<188,E36<6.3),"Underused but Efficient","Efficient / High Turnover"))) -> Underused but Efficient | I36: Massachusetts | J36: Kansas | K36: New Mexico | L36: Puerto Rico
A37: Ohio | B37: 290867 | C37: 1651439 | D37: 231 | E37: 5.677643 | F37: =IF(AND(D37>188,E37>6.3),"System Pressure",IF(AND(D37<188,E37>6.3),"Inefficient",IF(AND(D37<188,E37<6.3),"Underused but Efficient","Efficient / High Turnover"))) -> Efficient / High Turnover | I37: Mississippi | J37: Louisiana | K37: North Dakota | L37: Vermont
A38: Oklahoma | B38: 64145 | C38: 362229 | D38: 238 | E38: 5.6470341 | F38: =IF(AND(D38>188,E38>6.3),"System Pressure",IF(AND(D38<188,E38>6.3),"Inefficient",IF(AND(D38<188,E38<6.3),"Underused but Efficient","Efficient / High Turnover"))) -> Efficient / High Turnover | I38: New York | J38: Michigan | K38: South Dakota | L38: Washington
A39: Oregon | B39: 68523 | C39: 442949 | D39: 146 | E39: 6.4642383 | F39: =IF(AND(D39>188,E39>6.3),"System Pressure",IF(AND(D39<188,E39>6.3),"Inefficient",IF(AND(D39<188,E39<6.3),"Underused but Efficient","Efficient / High Turnover"))) -> Inefficient | I39: North Carolina | J39: Missouri | K39: Utah
A40: Pennsylvania | B40: 316201 | C40: 1807692 | D40: 227 | E40: 5.7169079 | F40: =IF(AND(D40>188,E40>6.3),"System Pressure",IF(AND(D40<188,E40>6.3),"Inefficient",IF(AND(D40<188,E40<6.3),"Underused but Efficient","Efficient / High Turnover"))) -> Efficient / High Turnover | I40: South Carolina | J40: Nevada | K40: Wisconsin
A41: Puerto Rico | B41: 25823 | C41: 152274 | D41: 173 | E41: 6.9241052 | F41: =IF(AND(D41>188,E41>6.3),"System Pressure",IF(AND(D41<188,E41>6.3),"Inefficient",IF(AND(D41<188,E41<6.3),"Underused but Efficient","Efficient / High Turnover"))) -> Inefficient | I41: Tennessee | J41: New Jersey
A42: Rhode Island | B42: 105733 | C42: 677202 | D42: 205 | E42: 5.8968362 | F42: =IF(AND(D42>188,E42>6.3),"System Pressure",IF(AND(D42<188,E42>6.3),"Inefficient",IF(AND(D42<188,E42<6.3),"Underused but Efficient","Efficient / High Turnover"))) -> Efficient / High Turnover | I42: Virginia | J42: Ohio
A43: South Carolina | B43: 4293 | C43: 26231 | D43: 224 | E43: 6.404831 | F43: =IF(AND(D43>188,E43>6.3),"System Pressure",IF(AND(D43<188,E43>6.3),"Inefficient",IF(AND(D43<188,E43<6.3),"Underused but Efficient","Efficient / High Turnover"))) -> System Pressure | J43: Oklahoma
A44: South Dakota | B44: 150603 | C44: 973729 | D44: 76 | E44: 6.1101794 | F44: =IF(AND(D44>188,E44>6.3),"System Pressure",IF(AND(D44<188,E44>6.3),"Inefficient",IF(AND(D44<188,E44<6.3),"Underused but Efficient","Efficient / High Turnover"))) -> Underused but Efficient | J44: Pennsylvania
A45: Tennessee | B45: 502080 | C45: 2935505 | D45: 219 | E45: 6.4655352 | F45: =IF(AND(D45>188,E45>6.3),"System Pressure",IF(AND(D45<188,E45>6.3),"Inefficient",IF(AND(D45<188,E45<6.3),"Underused but Efficient","Efficient / High Turnover"))) -> System Pressure | J45: Rhode Island
A46: Texas | B46: 27756 | C46: 125253 | D46: 227 | E46: 5.8466878 | F46: =IF(AND(D46>188,E46>6.3),"System Pressure",IF(AND(D46<188,E46>6.3),"Inefficient",IF(AND(D46<188,E46<6.3),"Underused but Efficient","Efficient / High Turnover"))) -> Efficient / High Turnover | J46: Texas
A47: Utah | B47: 5594 | C47: 39814 | D47: 137 | E47: 4.5126459 | F47: =IF(AND(D47>188,E47>6.3),"System Pressure",IF(AND(D47<188,E47>6.3),"Inefficient",IF(AND(D47<188,E47<6.3),"Underused but Efficient","Efficient / High Turnover"))) -> Underused but Efficient | J47: West Virginia
A48: Vermont | B48: 118522 | C48: 753701 | D48: 130 | E48: 7.1172685 | F48: =IF(AND(D48>188,E48>6.3),"System Pressure",IF(AND(D48<188,E48>6.3),"Inefficient",IF(AND(D48<188,E48<6.3),"Underused but Efficient","Efficient / High Turnover"))) -> Inefficient
A49: Virginia | B49: 94435 | C49: 700088 | D49: 222 | E49: 6.3591654 | F49: =IF(AND(D49>188,E49>6.3),"System Pressure",IF(AND(D49<188,E49>6.3),"Inefficient",IF(AND(D49<188,E49<6.3),"Underused but Efficient","Efficient / High Turnover"))) -> System Pressure
...

Sheet Longest Hospital Stay
A1: State | B1: Average Length of Stay (Days)
A2: New York | B2: 6.7752512
A3: New Hampshire | B3: 6.8183873
A4: Puerto Rico | B4: 6.9241052
A5: Maryland | B5: 7.1131243
A6: Vermont | B6: 7.1172685
A7: Washington | B7: 7.4134378
A8: Maine | B8: 7.4372949
A9: Delaware | B9: 7.6350638
A10: Hawaii | B10: 7.8628249
A11: District of Columbia | B11: 8.754179
A12: State | B12: 7.3850937

Sheet Shortest Hospital Stay
A1: State | B1: Average Length of Stay (Days)
A2: Utah | B2: 4.5126459
A3: Kansas | B3: 5.2660328
A4: Wyoming | B4: 5.5614458
A5: Colorado | B5: 5.5674924
A6: Oklahoma | B6: 5.6470341
A7: Ohio | B7: 5.677643
A8: California | B8: 5.6851283
A9: Pennsylvania | B9: 5.7169079
A10: Iowa | B10: 5.747161
A11: Arkansas | B11: 5.7532427
A12: State | B12: 5.5134734
G29: Axis truncated for better comparison

Sheet Utilization Rate by State abs
A3: States | B3: Discharges Per 1,000 Medicare Advantage Part A Enrollees | G3: States | H3: Discharges Per 1,000 Medicare Advantage Part A Enrollees
A4: Alabama | B4: 225 | G4: Wisconsin | H4: 147
A5: Texas | B5: 227 | G5: Oregon | H5: 146
A6: Pennsylvania | B6: 227 | G6: Minnesota | H6: 145
A7: Massachusetts | B7: 228 | G7: Utah | H7: 137
A8: New Jersey | B8: 230 | G8: Montana | H8: 137
A9: Ohio | B9: 231 | G9: Vermont | H9: 130
A10: Missouri | B10: 232 | G10: Idaho | H10: 126
A11: Arkansas | B11: 235 | G11: Maine | H11: 120
A12: Oklahoma | B12: 238 | G12: South Dakota | H12: 76
A13: District of Columbia | B13: 268 | G13: North Dakota | H13: 70

Sheet Quadrants of Efficiency
A3: Quadranrt | B3: States | C3: Count of States
A4: Efficient / High Turnover | C4: 18
A5: Inefficient | C5: 9
A6: System Pressure | C6: 13
A7: Underused but Efficient | C7: 12
A8: Grand Total | C8: 52

Sheet Mortality Rate vs LOS
A1: Area of Residence | B1: Mortality Rate | C1: LOS
A2: Puerto Rico | B2: 0.075976839 | C2: 6.9241052
A3: Washington | B3: 0.056652724 | C3: 7.4134378
A4: Montana | B4: 0.054681218 | C4: 6.2218265
A5: District of Columbia | B5: 0.054080629 | C5: 8.754179
A6: Oregon | B6: 0.053339755 | C6: 6.4642383
A7: Hawaii | B7: 0.050112098 | C7: 7.8628249
A8: Tennessee | B8: 0.048192931 | C8: 6.4655352
A9: Nebraska | B9: 0.047804933 | C9: 6.4015049
A10: Virginia | B10: 0.046818312 | C10: 6.3591654
A11: California | B11: 0.046544491 | C11: 5.6851283
A12: New Mexico | B12: 0.045482664 | C12: 5.9471824
A13: New Hampshire | B13: 0.044529698 | C13: 6.8183873
... A53: Rhode Island | B53: 0.016032219 | C53: 5.8968362

Sheet Utilization Rate by State
A3: State | B3: Utilization Rate | D3: State | E3: Utilization Rate
A4: Massachusetts | B4: 0.14738729 | D4: New Hampshire | E4: 0.10625922
A5: Kentucky | B5: 0.14756821 | D5: Wisconsin | E5: 0.10434661
A6: South Carolina | B6: 0.14939201 | D6: Montana | E6: 0.1024481
A7: Pennsylvania | B7: 0.15044181 | D7: Utah | E7: 0.10162516
A8: Alabama | B8: 0.15078018 | D8: Minnesota | E8: 0.10139901
A9: Ohio | B9: 0.15124094 | D9: Idaho | E9: 0.09638115
A10: Missouri | B10: 0.15188294 | D10: Vermont | E10: 0.09164941
A11: Arkansas | B11: 0.15436261 | D11: Maine | E11: 0.08956805
A12: Oklahoma | B12: 0.16028529 | D12: South Dakota | E12: 0.053948022
A13: District of Columbia | B13: 0.16196758 | D13: North Dakota | E13: 0.047820903
A14: Grand Total | B14: 0.1509363 | D14: Grand Total | E14: 0.098714837

Sheet Efficiency_Index_Map
A1: State | B1: Efficiency Index
A2: Utah | B2: 0.22216817
A3: Kansas | B3: 0.18989848
A4: Wyoming | B4: 0.18011607
A5: Colorado | B5: 0.17982653
A6: Oklahoma | B6: 0.17706094
A7: Ohio | B7: 0.17576966
A8: California | B8: 0.17539655
A9: Pennsylvania | B9: 0.17511379
A10: Iowa | B10: 0.17384959
A11: Missouri | B11: 0.17360202
A12: Arkansas | B12: 0.173506
A13: Idaho | B13: 0.17247516
... A29: Wisconsin | B29: 0.16183546
A30: Nevada | B30: 0.16150257 | H30: low | I30: #DEEBF7
A31: Montana | B31: 0.16046288 | H31: high | I31: #08306B
A32: Virginia | B32: 0.15702585
A33: South Carolina | B33: 0.15630451
A34: North Carolina | B34: 0.15627277
A35: Nebraska | B35: 0.15590779
A36: Oregon | B36: 0.15499926
A37: Tennessee | B37: 0.15453769
A38: Massachusetts | B38: 0.15296778
A39: Mississippi | B39: 0.1524627
A40: Alabama | B40: 0.15131544
A41: Kentucky | B41: 0.14975187
A42: Alaska | B42: 0.14966992
A43: Georgia | B43: 0.14923475
... A54: Grand Total | B54: 0.15860204

Sheet Discharges per Inpatient Day
G2: discharge rate per bed-day
A3: State | B3: Total Days Per 1,000 Medicare Advantage Part A Enrollees | C3: Discharges Per 1,000 Medicare Advantage Part A Enrollees | D3: Efficiency Index | G3: Highest Discharge Rate per Inpatient Day
A4: Utah | B4: 616.65 | C4: 137 | D4: 0.22216817 | G4: State | H4: Efficiency Index
A5: Kansas | B5: 1111.12 | C5: 211 | D5: 0.18989848 | G5: =INDEX('Discharges per Inpatient Day'!$A$4:$A$55,MATCH(LARGE('Discharges per Inpatient Day'!$D$4:$D$55,ROW()-4),'Discharges per Inpatient Day'!$D$4:$D$55,0)) -> Utah | H5: =LARGE('Discharges per Inpatient Day'!$D$4:$D$55,ROW()-4) -> 0.22216817
A6: Wyoming | B6: 899.42 | C6: 162 | D6: 0.18011607 | G6: =INDEX('Discharges per Inpatient Day'!$A$4:$A$55,MATCH(LARGE('Discharges per Inpatient Day'!$D$4:$D$55,ROW()-4),'Discharges per Inpatient Day'!$D$4:$D$55,0)) -> Kansas | H6: =LARGE('Discharges per Inpatient Day'!$D$4:$D$55,ROW()-4) -> 0.18989848
A7: Colorado | B7: 911.99 | C7: 164 | D7: 0.17982653 | G7: =INDEX('Discharges per Inpatient Day'!$A$4:$A$55,MATCH(LARGE('Discharges per Inpatient Day'!$D$4:$D$55,ROW()-4),'Discharges per Inpatient Day'!$D$4:$D$55,0)) -> Wyoming | H7: =LARGE('Discharges per Inpatient Day'!$D$4:$D$55,ROW()-4) -> 0.18011607
A8: Oklahoma | B8: 1344.17 | C8: 238 | D8: 0.17706094 | G8: =INDEX('Discharges per Inpatient Day'!$A$4:$A$55,MATCH(LARGE('Discharges per Inpatient Day'!$D$4:$D$55,ROW()-4),'Discharges per Inpatient Day'!$D$4:$D$55,0)) -> Colorado | H8: =LARGE('Discharges per Inpatient Day'!$D$4:$D$55,ROW()-4) -> 0.17982653
A9: Ohio | B9: 1314.22 | C9: 231 | D9: 0.17576966 | G9: =INDEX('Discharges per Inpatient Day'!$A$4:$A$55,MATCH(LARGE('Discharges per Inpatient Day'!$D$4:$D$55,ROW()-4),'Discharges per Inpatient Day'!$D$4:$D$55,0)) -> Oklahoma | H9: =LARGE('Discharges per Inpatient Day'!$D$4:$D$55,ROW()-4) -> 0.17706094
A10: California | B10: 917.92 | C10: 161 | D10: 0.17539655
A11: Pennsylvania | B11: 1296.3 | C11: 227 | D11: 0.17511379
A12: Iowa | B12: 931.84 | C12: 162 | D12: 0.17384959
A13: Missouri | B13: 1336.39 | C13: 232 | D13: 0.17360202
A14: Arkansas | B14: 1354.42 | C14: 235 | D14: 0.173506
A15: Idaho | B15: 730.54 | C15: 126 | D15: 0.17247516 | G15: Lowest Discharge Rate per Inpatient Day
A16: Minnesota | B16: 841.4 | C16: 145 | D16: 0.17233183 | G16: State | H16: Efficiency Index
A17: Arizona | B17: 1140.79 | C17: 195 | D17: 0.17093418 | G17: =INDEX('Discharges per Inpatient Day'!$A$4:$A$55,MATCH(SMALL('Discharges per Inpatient Day'!$D$4:$D$55,ROW()-16),'Discharges per Inpatient Day'!$D$4:$D$55,0)) -> Dist. of Columbia | H17: =SMALL('Discharges per Inpatient Day'!$D$4:$D$55,ROW()-16) -> 0.1140877
A18: Texas | B18: 1330.01 | C18: 227 | D18: 0.17067541 | G18: =INDEX('Discharges per Inpatient Day'!$A$4:$A$55,MATCH(SMALL('Discharges per Inpatient Day'!$D$4:$D$55,ROW()-16),'Discharges per Inpatient Day'!$D$4:$D$55,0)) -> Hawaii | H18: =SMALL('Discharges per Inpatient Day'!$D$4:$D$55,ROW()-16) -> 0.12706683
A19: Rhode Island | B19: 1206.06 | C19: 205 | D19: 0.16997496 | G19: =INDEX('Discharges per Inpatient Day'!$A$4:$A$55,MATCH(SMALL('Discharges per Inpatient Day'!$D$4:$D$55,ROW()-16),'Discharges per Inpatient Day'!$D$4:$D$55,0)) -> Delaware | H19: =SMALL('Discharges per Inpatient Day'!$D$4:$D$55,ROW()-16) -> 0.13096073
A20: Florida | B20: 1279.98 | C20: 217 | D20: 0.1695339 | G20: =INDEX('Discharges per Inpatient Day'!$A$4:$A$55,MATCH(SMALL('Discharges per Inpatient Day'!$D$4:$D$55,ROW()-16),'Discharges per Inpatient Day'!$D$4:$D$55,0)) -> Maine | H20: =SMALL('Discharges per Inpatient Day'!$D$4:$D$55,ROW()-16) -> 0.1344071
A21: Louisiana | B21: 1212.17 | C21: 205 | D21: 0.16911819 | G21: =INDEX('Discharges per Inpatient Day'!$A$4:$A$55,MATCH(SMALL('Discharges per Inpatient Day'!$D$4:$D$55,ROW()-16),'Discharges per Inpatient Day'!$D$4:$D$55,0)) -> Washington | H21: =SMALL('Discharges per Inpatient Day'!$D$4:$D$55,ROW()-16) -> 0.13500874
A22: New Mexico | B22: 985.64 | C22: 166 | D22: 0.16841849
A23: Indiana | B23: 1288.38 | C23: 216 | D23: 0.1676524
A24: West Virginia | B24: 1256.83 | C24: 208 | D24: 0.16549573
A25: Illinois | B25: 1330.57 | C25: 220 | D25: 0.16534267
A26: North Dakota | B26: 426.31 | C26: 70 | D26: 0.16419976
A27: South Dakota | B27: 465.65 | C27: 76 | D27: 0.16321271
A28: Connecticut | B28: 1209.87 | C28: 197 | D28: 0.16282741
A29: Michigan | B29: 1266.34 | C29: 206 | D29: 0.16267353
A30: New Jersey | B30: 1417.59 | C30: 230 | D30: 0.16224719
A31: Wisconsin | B31: 908.33 | C31: 147 | D31: 0.16183546
A32: Nevada | B32: 1337.44 | C32: 216 | D32: 0.16150257
A33: Montana | B33: 853.78 | C33: 137 | D33: 0.16046288
... A56: Grand Total | B56: 61808.79 | C56: 9803 | D56: 0.15860204

Sheet ER Admition Analysis
A3: State | B3: ER discharge rate
A4: Puerto Rico | B4: 0.2045867
A5: South Dakota | B5: 0.70882833
A6: Wisconsin | B6: 0.71847605
A7: Nebraska | B7: 0.71990269
A8: Vermont | B8: 0.73131927
A9: Minnesota | B9: 0.73521039
A10: Montana | B10: 0.73727743
A11: Maine | B11: 0.73844789
A12: Utah | B12: 0.73904741
A13: Iowa | B13: 0.7403058
A14: Idaho | B14: 0.74641242
A15: Kansas | B15: 0.74936569
... A55: District of Columbia | B55: 0.87526338

Sheet ER Admition Analysis table
A1: State | B1: ER discharge rate | K1: State | L1: ER discharge rate
A2: Virginia | B2: 0.82479202 | K2: Puerto Rico | L2: 0.2045867
A3: California | B3: 0.82933171 | K3: South Dakota | L3: 0.70882833
A4: Florida | B4: 0.83073679 | K4: Wisconsin | L4: 0.71847605
A5: Alaska | B5: 0.84807256 | K5: Nebraska | L5: 0.71990269
A6: Rhode Island | B6: 0.85048213 | K6: Vermont | L6: 0.73131927
A7: New Jersey | B7: 0.86200587 | K7: Minnesota | L7: 0.73521039
A8: Delaware | B8: 0.86252772 | K8: Montana | L8: 0.73727743
A9: Hawaii | B9: 0.87017354 | K9: Maine | L9: 0.73844789
A10: Nevada | B10: 0.87136951 | K10: Utah | L10: 0.73904741
A11: District of Columbia | B11: 0.87526338 | K11: Iowa | L11: 0.7403058

Sheet Inpatient Mortality Rate
A3: state | B3: Discharged Dead | C3: Total Discharges | D3: Mortality Rate
A4: Alabama | B4: 4923 | C4: 132442 | D4: 0.037170988
A5: Alaska | B5: 19 | C5: 441 | D5: 0.0430839
A6: Arizona | B6: 5563 | C6: 132170 | D6: 0.042089733
A7: Arkansas | B7: 1998 | C7: 58207 | D7: 0.034325768
A8: California | B8: 24077 | C8: 517290 | D8: 0.046544491
A9: Colorado | B9: 3076 | C9: 77668 | D9: 0.03960447
A10: Connecticut | B10: 2866 | C10: 71924 | D10: 0.039847617
A11: Delaware | B11: 511 | C11: 13079 | D11: 0.039070265
A12: District of Columbia | B12: 385 | C12: 7119 | D12: 0.054080629
A13: Florida | B13: 14817 | C13: 562993 | D13: 0.026318267
A14: Georgia | B14: 7458 | C14: 207197 | D14: 0.03599473
A15: Hawaii | B15: 1207 | C15: 24086 | D15: 0.050112098
... A54: Wisconsin | B54: 4093 | C54: 95935 | D54: 0.042664304
A55: Wyoming | B55: 66 | C55: 1660 | D55: 0.039759036 | F55: Mortality Rate
A56: Grand Total | B56: 240856 | C56: 5982652 | D56: 0.040259069 | F56: =GETPIVOTDATA(" Discharged Dead",$A$3)*100/GETPIVOTDATA(" Total Discharges",$A$3) -> 4.0259069

Sheet MOrtality Rate Visaul Table
A1: state | B1: Mortality Rate
A2: California | B2: 0.046544491
A3: Virginia | B3: 0.046818312
A4: Nebraska | B4: 0.047804933
A5: Tennessee | B5: 0.048192931
A6: Hawaii | B6: 0.050112098
A7: Oregon | B7: 0.053339755
A8: District of Columbia | B8: 0.054080629
A9: Montana | B9: 0.054681218
A10: Washington | B10: 0.056652724
A11: Puerto Rico | B11: 0.075976839
A12: New Mexico | B12: 0.045482664
A13: New Hampshire | B13: 0.044529698
... A54: Rhode Island | B54: 0.016032219

Sheet Dashboard
G2: Medicare Advantage Inpatient Utilization Dashboard Source: CMS Data | All 50 States + DC | 2022
D3: =KPI!L15 -> 188.51923 | G3: =KPI!L16 -> 6.1277113 | J3: =KPI!M17 -> 36,7M | M3: =KPI!M19 -> 4,8M | P3: =KPI!L20 -> 0.79587146 | S3: =KPI!L21 -> 0.040259069
D5: Hospital Utilization | G5: Average Length | J5: Impatient Days | M5: ER | P5: ER | S5: Mortality Rate
D6: per 1,000 Enrollees | G6: Stay (days) | M6: Discharges | P6: Dependancy Rate
Q13: ='Discharges per Inpatient Day'!G4 -> State | R13: ='Discharges per Inpatient Day'!H4 -> Efficiency Index | T13: ='Discharges per Inpatient Day'!G16 -> State | U13: ='Discharges per Inpatient Day'!H16 -> Efficiency Index
Q14: ='Discharges per Inpatient Day'!G5 -> Utah | R14: ='Discharges per Inpatient Day'!H5 -> 0.22216817 | T14: ='Discharges per Inpatient Day'!G17 -> Dist. of Columbia | U14: ='Discharges per Inpatient Day'!H17 -> 0.1140877
Q15: ='Discharges per Inpatient Day'!G6 -> Kansas | R15: ='Discharges per Inpatient Day'!H6 -> 0.18989848 | T15: ='Discharges per Inpatient Day'!G18 -> Hawaii | U15: ='Discharges per Inpatient Day'!H18 -> 0.12706683
Q16: ='Discharges per Inpatient Day'!G7 -> Wyoming | R16: ='Discharges per Inpatient Day'!H7 -> 0.18011607 | T16: ='Discharges per Inpatient Day'!G19 -> Delaware | U16: ='Discharges per Inpatient Day'!H19 -> 0.13096073
Q17: ='Discharges per Inpatient Day'!G8 -> Colorado | R17: ='Discharges per Inpatient Day'!H8 -> 0.17982653 | T17: ='Discharges per Inpatient Day'!G20 -> Maine | U17: ='Discharges per Inpatient Day'!H20 -> 0.1344071
Q18: ='Discharges per Inpatient Day'!G9 -> Oklahoma | R18: ='Discharges per Inpatient Day'!H9 -> 0.17706094 | T18: ='Discharges per Inpatient Day'!G21 -> Washington | U18: ='Discharges per Inpatient Day'!H21 -> 0.13500874

Sheet State Level Data
A1: Area of Residence | B1: Total Days Per 1,000 Medicare Advantage Part A Enrollees | C1: Utilization Level | D1: LOS | F1: Mortality Rate | H1: System Type | J1: Efficient_X | K1: Efficient_Y | L1: Pressure_X | M1: Pressure_Y | N1: Ubderused but efficient | O1: Ubderused but efficient | P1: Inafficient | Q1: Inafficient
A2: Alabama | B2: 1486.96 | C2: =IF(B2 > AVERAGE(B:B), "High", "Low") -> High | D2: 6.6037813 | E2: =IF(D2>AVERAGE(D:D),"Long","Short") -> Long | F2: 0.037170988 | H2: =IF(C2="High",IF(E2="Short","Efficient / High Turnover","System Pressure"), IF(E2="Short","Underused but Efficient","Inefficient")) -> System Pressure | J2: =IF($H2="Efficient / High Turnover",$B2,NA()) -> #N/A | K2: =IF($H2="Efficient / High Turnover",$D2,NA()) -> #N/A | L2: =IF($H2="System Pressure",$B2,NA()) -> 1486.96 | M2: =IF($H2="System Pressure",$D2,NA()) -> 6.6037813 | N2: =IF($H2="Underused but Efficient",$B2,NA()) -> #N/A | O2: =IF($H2="Underused but Efficient",$D2,NA()) -> #N/A | P2: =IF($H2="Inefficient",$B2,NA()) -> #N/A | Q2: =IF($H2="Inefficient",$D2,NA()) -> #N/A
A3: Alaska | B3: 1122.47 | C3: =IF(B3 > AVERAGE(B:B), "High", "Low") -> Low | D3: 6.7006803 | E3: =IF(D3>AVERAGE(D:D),"Long","Short") -> Long | F3: 0.0430839 | H3: =IF(C3="High",IF(E3="Short","Efficient / High Turnover","System Pressure"), IF(E3="Short","Underused but Efficient","Inefficient")) -> Inefficient | J3: =IF($H3="Efficient / High Turnover",$B3,NA()) -> #N/A | K3: =IF($H3="Efficient / High Turnover",$D3,NA()) -> #N/A | L3: =IF($H3="System Pressure",$B3,NA()) -> #N/A | M3: =IF($H3="System Pressure",$D3,NA()) -> #N/A | N3: =IF($H3="Underused but Efficient",$B3,NA()) -> #N/A | O3: =IF($H3="Underused but Efficient",$D3,NA()) -> #N/A | P3: =IF($H3="Inefficient",$B3,NA()) -> 1122.47 | Q3: =IF($H3="Inefficient",$D3,NA()) -> 6.7006803
A4: Arizona | B4: 1140.79 | C4: =IF(B4 > AVERAGE(B:B), "High", "Low") -> Low | D4: 5.8389574 | E4: =IF(D4>AVERAGE(D:D),"Long","Short") -> Short | F4: 0.042089733 | H4: =IF(C4="High",IF(E4="Short","Efficient / High Turnover","System Pressure"), IF(E4="Short","Underused but Efficient","Inefficient")) -> Underused but Efficient | J4: =IF($H4="Efficient / High Turnover",$B4,NA()) -> #N/A | K4: =IF($H4="Efficient / High Turnover",$D4,NA()) -> #N/A | L4: =IF($H4="System Pressure",$B4,NA()) -> #N/A | M4: =IF($H4="System Pressure",$D4,NA()) -> #N/A | N4: =IF($H4="Underused but Efficient",$B4,NA()) -> 1140.79 | O4: =IF($H4="Underused but Efficient",$D4,NA()) -> 5.8389574 | P4: =IF($H4="Inefficient",$B4,NA()) -> #N/A | Q4: =IF($H4="Inefficient",$D4,NA()) -> #N/A | R4: System Pressure | S4: =COUNTIF(H:H,"System Pressure") -> 15 | T4: =AVERAGEIF(H:H,"System Pressure",F:F) -> 0.045574804
A5: Arkansas | B5: 1354.42 | C5: =IF(B5 > AVERAGE(B:B), "High", "Low") -> High | D5: 5.7532427 | E5: =IF(D5>AVERAGE(D:D),"Long","Short") -> Short | F5: 0.034325768 | H5: =IF(C5="High",IF(E5="Short","Efficient / High Turnover","System Pressure"), IF(E5="Short","Underused but Efficient","Inefficient")) -> Efficient / High Turnover | J5: =IF($H5="Efficient / High Turnover",$B5,NA()) -> 1354.42 | K5: =IF($H5="Efficient / High Turnover",$D5,NA()) -> 5.7532427 | L5: =IF($H5="System Pressure",$B5,NA()) -> #N/A | M5: =IF($H5="System Pressure",$D5,NA()) -> #N/A | N5: =IF($H5="Underused but Efficient",$B5,NA()) -> #N/A | O5: =IF($H5="Underused but Efficient",$D5,NA()) -> #N/A | P5: =IF($H5="Inefficient",$B5,NA()) -> #N/A | Q5: =IF($H5="Inefficient",$D5,NA()) -> #N/A | R5: Efficient / High Turnover | S5: =COUNTIF(H:H,"Efficient / High Turnover") -> 16 | T5: =AVERAGEIF(H:H,"Efficient / High Turnover",F:F) -> 0.03815553
A6: California | B6: 917.92 | C6: =IF(B6 > AVERAGE(B:B), "High", "Low") -> Low | D6: 5.6851283 | E6: =IF(D6>AVERAGE(D:D),"Long","Short") -> Short | F6: 0.046544491 | H6: =IF(C6="High",IF(E6="Short","Efficient / High Turnover","System Pressure"), IF(E6="Short","Underused but Efficient","Inefficient")) -> Underused but Efficient | J6: =IF($H6="Efficient / High Turnover",$B6,NA()) -> #N/A | K6: =IF($H6="Efficient / High Turnover",$D6,NA()) -> #N/A | L6: =IF($H6="System Pressure",$B6,NA()) -> #N/A | M6: =IF($H6="System Pressure",$D6,NA()) -> #N/A | N6: =IF($H6="Underused but Efficient",$B6,NA()) -> 917.92 | O6: =IF($H6="Underused but Efficient",$D6,NA()) -> 5.6851283 | P6: =IF($H6="Inefficient",$B6,NA()) -> #N/A | Q6: =IF($H6="Inefficient",$D6,NA()) -> #N/A | R6: Underused but Efficient | S6: =COUNTIF(H:H, "Underused but Efficient") -> 15 | T6: =AVERAGEIF(H:H,"Underused but Efficient",F:F) -> 0.0410563
A7: Colorado | B7: 911.99 | C7: =IF(B7 > AVERAGE(B:B), "High", "Low") -> Low | D7: 5.5674924 | E7: =IF(D7>AVERAGE(D:D),"Long","Short") -> Short | F7: 0.03960447 | H7: =IF(C7="High",IF(E7="Short","Efficient / High Turnover","System Pressure"), IF(E7="Short","Underused but Efficient","Inefficient")) -> Underused but Efficient | J7: =IF($H7="Efficient / High Turnover",$B7,NA()) -> #N/A | K7: =IF($H7="Efficient / High Turnover",$D7,NA()) -> #N/A | L7: =IF($H7="System Pressure",$B7,NA()) -> #N/A | M7: =IF($H7="System Pressure",$D7,NA()) -> #N/A | N7: =IF($H7="Underused but Efficient",$B7,NA()) -> 911.99 | O7: =IF($H7="Underused but Efficient",$D7,NA()) -> 5.5674924 | P7: =IF($H7="Inefficient",$B7,NA()) -> #N/A | Q7: =IF($H7="Inefficient",$D7,NA()) -> #N/A | R7: Inefficient | S7: =COUNTIF(H:H, "Inefficient") -> 7 | T7: =AVERAGEIF(H:H,"Inefficient",F:F) -> 0.044867651
A8: Connecticut | B8: 1209.87 | C8: =IF(B8 > AVERAGE(B:B), "High", "Low") -> High | D8: 6.1300957 | E8: =IF(D8>AVERAGE(D:D),"Long","Short") -> Short | F8: 0.039847617 | H8: =IF(C8="High",IF(E8="Short","Efficient / High Turnover","System Pressure"), IF(E8="Short","Underused but Efficient","Inefficient")) -> Efficient / High Turnover | J8: =IF($H8="Efficient / High Turnover",$B8,NA()) -> 1209.87 | K8: =IF($H8="Efficient / High Turnover",$D8,NA()) -> 6.1300957 | L8: =IF($H8="System Pressure",$B8,NA()) -> #N/A | M8: =IF($H8="System Pressure",$D8,NA()) -> #N/A | N8: =IF($H8="Underused but Efficient",$B8,NA()) -> #N/A | O8: =IF($H8="Underused but Efficient",$D8,NA()) -> #N/A | P8: =IF($H8="Inefficient",$B8,NA()) -> #N/A | Q8: =IF($H8="Inefficient",$D8,NA()) -> #N/A
A9: Delaware | B9: 1611.17 | C9: =IF(B9 > AVERAGE(B:B), "High", "Low") -> High | D9: 7.6350638 | E9: =IF(D9>AVERAGE(D:D),"Long","Short") -> Long | F9: 0.039070265 | H9: =IF(C9="High",IF(E9="Short","Efficient / High Turnover","System Pressure"), IF(E9="Short","Underused but Efficient","Inefficient")) -> System Pressure | J9: =IF($H9="Efficient / High Turnover",$B9,NA()) -> #N/A | K9: =IF($H9="Efficient / High Turnover",$D9,NA()) -> #N/A | L9: =IF($H9="System Pressure",$B9,NA()) -> 1611.17 | M9: =IF($H9="System Pressure",$D9,NA()) -> 7.6350638 | N9: =IF($H9="Underused but Efficient",$B9,NA()) -> #N/A | O9: =IF($H9="Underused but Efficient",$D9,NA()) -> #N/A | P9: =IF($H9="Inefficient",$B9,NA()) -> #N/A | Q9: =IF($H9="Inefficient",$D9,NA()) -> #N/A
A10: District of Columbia | B10: 2349.07 | C10: =IF(B10 > AVERAGE(B:B), "High", "Low") -> High | D10: 8.754179 | E10: =IF(D10>AVERAGE(D:D),"Long","Short") -> Long | F10: 0.054080629 | H10: =IF(C10="High",IF(E10="Short","Efficient / High Turnover","System Pressure"), IF(E10="Short","Underused but Efficient","Inefficient")) -> System Pressure | J10: =IF($H10="Efficient / High Turnover",$B10,NA()) -> #N/A | K10: =IF($H10="Efficient / High Turnover",$D10,NA()) -> #N/A | L10: =IF($H10="System Pressure",$B10,NA()) -> 2349.07 | M10: =IF($H10="System Pressure",$D10,NA()) -> 8.754179 | N10: =IF($H10="Underused but Efficient",$B10,NA()) -> #N/A | O10: =IF($H10="Underused but Efficient",$D10,NA()) -> #N/A | P10: =IF($H10="Inefficient",$B10,NA()) -> #N/A | Q10: =IF($H10="Inefficient",$D10,NA()) -> #N/A
A11: Florida | B11: 1279.98 | C11: =IF(B11 > AVERAGE(B:B), "High", "Low") -> High | D11: 5.9117502 | E11: =IF(D11>AVERAGE(D:D),"Long","Short") -> Short | F11: 0.026318267 | H11: =IF(C11="High",IF(E11="Short","Efficient / High Turnover","System Pressure"), IF(E11="Short","Underused but Efficient","Inefficient")) -> Efficient / High Turnover | J11: =IF($H11="Efficient / High Turnover",$B11,NA()) -> 1279.98 | K11: =IF($H11="Efficient / High Turnover",$D11,NA()) -> 5.9117502 | L11: =IF($H11="System Pressure",$B11,NA()) -> #N/A | M11: =IF($H11="System Pressure",$D11,NA()) -> #N/A | N11: =IF($H11="Underused but Efficient",$B11,NA()) -> #N/A | O11: =IF($H11="Underused but Efficient",$D11,NA()) -> #N/A | P11: =IF($H11="Inefficient",$B11,NA()) -> #N/A | Q11: =IF($H11="Inefficient",$D11,NA()) -> #N/A
A12: Georgia | B12: 1494.29 | C12: =IF(B12 > AVERAGE(B:B), "High", "Low") -> High | D12: 6.7146484 | E12: =IF(D12>AVERAGE(D:D),"Long","Short") -> Long | F12: 0.03599473 | H12: =IF(C12="High",IF(E12="Short","Efficient / High Turnover","System Pressure"), IF(E12="Short","Underused but Efficient","Inefficient")) -> System Pressure | J12: =IF($H12="Efficient / High Turnover",$B12,NA()) -> #N/A | K12: =IF($H12="Efficient / High Turnover",$D12,NA()) -> #N/A | L12: =IF($H12="System Pressure",$B12,NA()) -> 1494.29 | M12: =IF($H12="System Pressure",$D12,NA()) -> 6.7146484 | N12: =IF($H12="Underused but Efficient",$B12,NA()) -> #N/A | O12: =IF($H12="Underused but Efficient",$D12,NA()) -> #N/A | P12: =IF($H12="Inefficient",$B12,NA()) -> #N/A | Q12: =IF($H12="Inefficient",$D12,NA()) -> #N/A
A13: Hawaii | B13: 1251.31 | C13: =IF(B13 > AVERAGE(B:B), "High", "Low") -> High | D13: 7.8628249 | E13: =IF(D13>AVERAGE(D:D),"Long","Short") -> Long | F13: 0.050112098 | H13: =IF(C13="High",IF(E13="Short","Efficient / High Turnover","System Pressure"), IF(E13="Short","Underused but Efficient","Inefficient")) -> System Pressure | J13: =IF($H13="Efficient / High Turnover",$B13,NA()) -> #N/A | K13: =IF($H13="Efficient / High Turnover",$D13,NA()) -> #N/A | L13: =IF($H13="System Pressure",$B13,NA()) -> 1251.31 | M13: =IF($H13="System Pressure",$D13,NA()) -> 7.8628249 | N13: =IF($H13="Underused but Efficient",$B13,NA()) -> #N/A | O13: =IF($H13="Underused but Efficient",$D13,NA()) -> #N/A | P13: =IF($H13="Inefficient",$B13,NA()) -> #N/A | Q13: =IF($H13="Inefficient",$D13,NA()) -> #N/A
A14: Idaho | B14: 730.54 | C14: =IF(B14 > AVERAGE(B:B), "High", "Low") -> Low | D14: 5.8106448 | E14: =IF(D14>AVERAGE(D:D),"Long","Short") -> Short | F14: 0.041625713 | H14: =IF(C14="High",IF(E14="Short","Efficient / High Turnover","System Pressure"), IF(E14="Short","Underused but Efficient","Inefficient")) -> Underused but Efficient | J14: =IF($H14="Efficient / High Turnover",$B14,NA()) -> #N/A | K14: =IF($H14="Efficient / High Turnover",$D14,NA()) -> #N/A | L14: =IF($H14="System Pressure",$B14,NA()) -> #N/A | M14: =IF($H14="System Pressure",$D14,NA()) -> #N/A | N14: =IF($H14="Underused but Efficient",$B14,NA()) -> 730.54 | O14: =IF($H14="Underused but Efficient",$D14,NA()) -> 5.8106448 | P14: =IF($H14="Inefficient",$B14,NA()) -> #N/A | Q14: =IF($H14="Inefficient",$D14,NA()) -> #N/A
A15: Illinois | B15: 1330.57 | C15: =IF(B15 > AVERAGE(B:B), "High", "Low") -> High | D15: 6.044458 | E15: =IF(D15>AVERAGE(D:D),"Long","Short") -> Short | F15: 0.03872529 | H15: =IF(C15="High",IF(E15="Short","Efficient / High Turnover","System Pressure"), IF(E15="Short","Underused but Efficient","Inefficient")) -> Efficient / High Turnover | J15: =IF($H15="Efficient / High Turnover",$B15,NA()) -> 1330.57 | K15: =IF($H15="Efficient / High Turnover",$D15,NA()) -> 6.044458 | L15: =IF($H15="System Pressure",$B15,NA()) -> #N/A | M15: =IF($H15="System Pressure",$D15,NA()) -> #N/A | N15: =IF($H15="Underused but Efficient",$B15,NA()) -> #N/A | O15: =IF($H15="Underused but Efficient",$D15,NA()) -> #N/A | P15: =IF($H15="Inefficient",$B15,NA()) -> #N/A | Q15: =IF($H15="Inefficient",$D15,NA()) -> #N/A
A16: Indiana | B16: 1288.38 | C16: =IF(B16 > AVERAGE(B:B), "High", "Low") -> High | D16: 5.9544597 | E16: =IF(D16>AVERAGE(D:D),"Long","Short") -> Short | F16: 0.042264549 | H16: =IF(C16="High",IF(E16="Short","Efficient / High Turnover","System Pressure"), IF(E16="Short","Underused but Efficient","Inefficient")) -> Efficient / High Turnover | J16: =IF($H16="Efficient / High Turnover",$B16,NA()) -> 1288.38 | K16: =IF($H16="Efficient / High Turnover",$D16,NA()) -> 5.9544597 | L16: =IF($H16="System Pressure",$B16,NA()) -> #N/A | M16: =IF($H16="System Pressure",$D16,NA()) -> #N/A | N16: =IF($H16="Underused but Efficient",$B16,NA()) -> #N/A | O16: =IF($H16="Underused but Efficient",$D16,NA()) -> #N/A | P16: =IF($H16="Inefficient",$B16,NA()) -> #N/A | Q16: =IF($H16="Inefficient",$D16,NA()) -> #N/A
A17: Iowa | B17: 931.84 | C17: =IF(B17 > AVERAGE(B:B), "High", "Low") -> Low | D17: 5.747161 | E17: =IF(D17>AVERAGE(D:D),"Long","Short") -> Short | F17: 0.043962922 | H17: =IF(C17="High",IF(E17="Short","Efficient / High Turnover","System Pressure"), IF(E17="Short","Underused but Efficient","Inefficient")) -> Underused but Efficient | J17: =IF($H17="Efficient / High Turnover",$B17,NA()) -> #N/A | K17: =IF($H17="Efficient / High Turnover",$D17,NA()) -> #N/A | L17: =IF($H17="System Pressure",$B17,NA()) -> #N/A | M17: =IF($H17="System Pressure",$D17,NA()) -> #N/A | N17: =IF($H17="Underused but Efficient",$B17,NA()) -> 931.84 | O17: =IF($H17="Underused but Efficient",$D17,NA()) -> 5.747161 | P17: =IF($H17="Inefficient",$B17,NA()) -> #N/A | Q17: =IF($H17="Inefficient",$D17,NA()) -> #N/A
A18: Kansas | B18: 1111.12 | C18: =IF(B18 > AVERAGE(B:B), "High", "Low") -> Low | D18: 5.2660328 | E18: =IF(D18>AVERAGE(D:D),"Long","Short") -> Short | F18: 0.037796378 | H18: =IF(C18="High",IF(E18="Short","Efficient / High Turnover","System Pressure"), IF(E18="Short","Underused but Efficient","Inefficient")) -> Underused but Efficient | J18: =IF($H18="Efficient / High Turnover",$B18,NA()) -> #N/A | K18: =IF($H18="Efficient / High Turnover",$D18,NA()) -> #N/A | L18: =IF($H18="System Pressure",$B18,NA()) -> #N/A | M18: =IF($H18="System Pressure",$D18,NA()) -> #N/A | N18: =IF($H18="Underused but Efficient",$B18,NA()) -> 1111.12 | O18: =IF($H18="Underused but Efficient",$D18,NA()) -> 5.2660328 | P18: =IF($H18="Inefficient",$B18,NA()) -> #N/A | Q18: =IF($H18="Inefficient",$D18,NA()) -> #N/A
A19: Kentucky | B19: 1489.13 | C19: =IF(B19 > AVERAGE(B:B), "High", "Low") -> High | D19: 6.6651133 | E19: =IF(D19>AVERAGE(D:D),"Long","Short") -> Long | F19: 0.042445763 | H19: =IF(C19="High",IF(E19="Short","Efficient / High Turnover","System Pressure"), IF(E19="Short","Underused but Efficient","Inefficient")) -> System Pressure | J19: =IF($H19="Efficient / High Turnover",$B19,NA()) -> #N/A | K19: =IF($H19="Efficient / High Turnover",$D19,NA()) -> #N/A | L19: =IF($H19="System Pressure",$B19,NA()) -> 1489.13 | M19: =IF($H19="System Pressure",$D19,NA()) -> 6.6651133 | N19: =IF($H19="Underused but Efficient",$B19,NA()) -> #N/A | O19: =IF($H19="Underused but Efficient",$D19,NA()) -> #N/A | P19: =IF($H19="Inefficient",$B19,NA()) -> #N/A | Q19: =IF($H19="Inefficient",$D19,NA()) -> #N/A
... A53: Puerto Rico | B53: 1201.23 | C53: =IF(B53 > AVERAGE(B:B), "High", "Low") -> High | D53: 5.5614458 | E53: =IF(D53>AVERAGE(D:D),"Long","Short") -> Short | F53: 0.039759036 | H53: =IF(C53="High",IF(E53="Short","Efficient / High Turnover","System Pressure"), IF(E53="Short","Underused but Efficient","Inefficient")) -> Efficient / High Turnover | J53: =IF($H53="Efficient / High Turnover",$B53,NA()) -> 1201.23 | K53: =IF($H53="Efficient / High Turnover",$D53,NA()) -> 5.5614458 | L53: =IF($H53="System Pressure",$B53,NA()) -> #N/A | M53: =IF($H53="System Pressure",$D53,NA()) -> #N/A | N53: =IF($H53="Underused but Efficient",$B53,NA()) -> #N/A | O53: =IF($H53="Underused but Efficient",$D53,NA()) -> #N/A | P53: =IF($H53="Inefficient",$B53,NA()) -> #N/A | Q53: =IF($H53="Inefficient",$D53,NA()) -> #N/A
C54: =IF(B54 > AVERAGE(B:B), "High", "Low") -> Low | E54: =IF(D54>AVERAGE(D:D),"Long","Short") -> Short | F54: 0.040259069 | H54: =IF(C54="High",IF(E54="Short","Efficient / High Turnover","System Pressure"), IF(E54="Short","Underused but Efficient","Inefficient")) -> Underused but Efficient | J54: =IF($H54="Efficient / High Turnover",$B54,NA()) -> #N/A | K54: =IF($H54="Efficient / High Turnover",$D54,NA()) -> #N/A | L54: =IF($H54="System Pressure",$B54,NA()) -> #N/A | M54: =IF($H54="System Pressure",$D54,NA()) -> #N/A | N54: =IF($H54="Underused but Efficient",$B54,NA()) -> 0 | O54: =IF($H54="Underused but Efficient",$D54,NA()) -> 0 | P54: =IF($H54="Inefficient",$B54,NA()) -> #N/A | Q54: =IF($H54="Inefficient",$D54,NA()) -> #N/A

Sheet KPI
A1: Area of Residence | B1: Discharges Per 1,000 Medicare Advantage Part A Enrollees | C1: Utilization Rate | D1: LOS | E1: Total Days of Care | F1: Total Discharges | G1: Total Discharges Beginning with Emergency Room Visit³ | H1: ER discharge rate | I1: Discharged Dead
A2: Alabama | B2: 225 | C2: 15.078018 | D2: 6.6037813 | E2: 874618 | F2: 132442 | G2: 102393 | H2: 0.77311578 | I2: 4923
A3: Alaska | B3: 168 | C3: 11.127991 | D3: 6.7006803 | E3: 2955 | F3: 441 | G3: 374 | H3: 0.84807256 | I3: 19
A4: Arizona | B4: 195 | C4: 13.211667 | D4: 5.8389574 | E4: 771735 | F4: 132170 | G4: 107025 | H4: 0.80975259 | I4: 5563
A5: Arkansas | B5: 235 | C5: 15.436261 | D5: 5.7532427 | E5: 334879 | F5: 58207 | G5: 44696 | H5: 0.76788015 | I5: 1998
A6: California | B6: 161 | C6: 11.09297 | D6: 5.6851283 | E6: 2940860 | F6: 517290 | G6: 429005 | H6: 0.82933171 | I6: 24077
A7: Colorado | B7: 164 | C7: 11.702724 | D7: 5.5674924 | E7: 432416 | F7: 77668 | G7: 60892 | H7: 0.78400371 | I7: 3076
A8: Connecticut | B8: 197 | C8: 13.068676 | D8: 6.1300957 | E8: 440901 | F8: 71924 | G8: 58991 | H8: 0.8201852 | I8: 2866
A9: Delaware | B9: 211 | C9: 14.025718 | D9: 7.6350638 | E9: 99859 | F9: 13079 | G9: 11281 | H9: 0.86252772 | I9: 511
A10: District of Columbia | B10: 268 | C10: 16.196758 | D10: 8.754179 | E10: 62321 | F10: 7119 | G10: 6231 | H10: 0.87526338 | I10: 385
A11: Florida | B11: 217 | C11: 14.14291 | D11: 5.9117502 | E11: 3328274 | F11: 562993 | G11: 467699 | H11: 0.83073679 | I11: 14817
A12: Georgia | B12: 223 | C12: 14.480333 | D12: 6.7146484 | E12: 1391255 | F12: 207197 | G12: 170280 | H12: 0.82182657 | I12: 7458
A13: Hawaii | B13: 159 | C13: 11.17087 | D13: 7.8628249 | E13: 189384 | F13: 24086 | G13: 20959 | H13: 0.87017354 | I13: 1207
A14: Idaho | B14: 126 | C14: 9.638115 | D14: 5.8106448 | E14: 118235 | F14: 20348 | G14: 15188 | H14: 0.74641242 | I14: 847
A15: Illinois | B15: 220 | C15: 14.25847 | D15: 6.044458 | E15: 1171422 | F15: 193801 | G15: 156335 | H15: 0.80667798 | I15: 7505 | K15: Hospital Utilization Rate (per 1,000) | L15: =B54 -> 188.51923
A16: Indiana | B16: 216 | C16: 14.555195 | D16: 5.9544597 | E16: 745284 | F16: 125164 | G16: 96793 | H16: 0.77332939 | I16: 5290 | K16: Average Length of Stay | L16: =E54/F54 -> 6.1277113
A17: Iowa | B17: 162 | C17: 11.456697 | D17: 5.747161 | E17: 192823 | F17: 33551 | G17: 24838 | H17: 0.7403058 | I17: 1475 | K17: Total Impatient Days | L17: =E54 -> 36659964 | M17: =ROUND(L17/1000000,1)&"M" -> 36,7M
A18: Kansas | B18: 211 | C18: 14.275429 | D18: 5.2660328 | E18: 180567 | F18: 34289 | G18: 25695 | H18: 0.74936569 | I18: 1296 | K18: Total Dischargers | L18: =F54 -> 5982652 | M18: =ROUND(L18/1000000,2)&"M" -> 5,98M
A19: Kentucky | B19: 223 | C19: 14.756821 | D19: 6.6651133 | E19: 685107 | F19: 102790 | G19: 78688 | H19: 0.76552194 | I19: 4363 | K19: Total ER Discharges | L19: =G54 -> 4761422 | M19: =ROUND(L19/1000000,1)&"M" -> 4,8M
A20: Louisiana | B20: 205 | C20: 13.790492 | D20: 5.9189296 | E20: 553852 | F20: 93573 | G20: 75137 | H20: 0.80297735 | I20: 3709 | K20: ER Admission Rate | L20: =G54/F54 -> 0.79587146
A21: Maine | B21: 120 | C21: 8.956805 | D21: 7.4372949 | E21: 167711 | F21: 22550 | G21: 16652 | H21: 0.73844789 | I21: 920 | K21: Mortality Rate | L21: =I54/F54 -> 0.040259069
A22: Maryland | B22: 201 | C22: 13.229973 | D22: 7.1131243 | E22: 298360 | F22: 41945 | G22: 34046 | H22: 0.81168196 | I22: 1797
A23: Massachusetts | B23: 228 | C23: 14.738729 | D23: 6.54288 | E23: 654517 | F23: 100035 | G23: 81024 | H23: 0.80995652 | I23: 2910
A24: Michigan | B24: 206 | C24: 13.531614 | D24: 6.13654 | E24: 1521371 | F24: 247920 | G24: 200186 | H24: 0.80746208 | I24: 9951
A25: Minnesota | B25: 145 | C25: 10.139901 | D25: 5.813962 | E25: 506524 | F25: 87122 | G25: 64053 | H25: 0.73521039 | I25: 3166
A26: Mississippi | B26: 216 | C26: 14.332224 | D26: 6.548326 | E26: 307660 | F26: 46983 | G26: 37892 | H26: 0.80650448 | I26: 1965
A27: Missouri | B27: 232 | C27: 15.188294 | D27: 5.7652282 | E27: 814817 | F27: 141333 | G27: 111037 | H27: 0.785641 | I27: 5984
A28: Montana | B28: 137 | C28: 10.24481 | D28: 6.2218265 | E28: 54161 | F28: 8705 | G28: 6418 | H28: 0.73727743 | I28: 476
A29: Nebraska | B29: 168 | C29: 11.704711 | D29: 6.4015049 | E29: 113153 | F29: 17676 | G29: 12725 | H29: 0.71990269 | I29: 845
A30: Nevada | B30: 216 | C30: 14.178945 | D30: 6.1920685 | E30: 356465 | F30: 57568 | G30: 50163 | H30: 0.87136951 | I30: 2311 | K30: Hospital Utilization Rate (per 1,000) | L30: 188.51923 | M30: 188.51923 | N30: 188.51923
A31: New Hampshire | B31: 153 | C31: 10.625922 | D31: 6.8183873 | E31: 99528 | F31: 14597 | G31: 11220 | H31: 0.76865109 | I31: 650 | K31: Average Length of Stay | L31: 6.2935757 | M31: 6.2935757 | N31: 6.2935757
A32: New Jersey | B32: 230 | C32: 14.726831 | D32: 6.1713534 | E32: 887058 | F32: 143738 | G32: 123903 | H32: 0.86200587 | I32: 5946 | K32: Total Impatient Days | L32: 36,7M | M32: 36659964
A33: New Mexico | B33: 166 | C33: 11.689694 | D33: 5.9471824 | E33: 201889 | F33: 33947 | G33: 26541 | H33: 0.78183639 | I33: 1544 | K33: Total Dischargers | L33: 6.0M | M33: 5982652 | N33: =ROUND(M33/1000000,2)&".M" -> 5,98.M
A34: New York | B34: 211 | C34: 14.031514 | D34: 6.7752512 | E34: 2596405 | F34: 383219 | G34: 313757 | H34: 0.81874072 | I34: 16588 | K34: ER Discharges | L34: 4,8M | M34: 4761422 | N34: =ROUND(M34/1000000,1)&"M" -> 4,8M
A35: North Carolina | B35: 193 | C35: 13.208252 | D35: 6.3972351 | E35: 1276274 | F35: 199504 | G35: 159772 | H35: 0.8008461 | I35: 8810 | K35: ER Admission Rate | L35: 0.79587146 | M35: 0.79587146 | N35: 0.79587146
A36: North Dakota | B36: 70 | C36: 4.7820903 | D36: 6.0652092 | E36: 16091 | F36: 2653 | G36: 2091 | H36: 0.78816434 | I36: 116 | K36: Mortality
A37: Ohio | B37: 231 | C37: 15.124094 | D37: 5.677643 | E37: 1651439 | F37: 290867 | G37: 230994 | H37: 0.79415678 | I37: 10870 | S37: 188.51923
A38: Oklahoma | B38: 238 | C38: 16.028529 | D38: 5.6470341 | E38: 362229 | F38: 64145 | G38: 49350 | H38: 0.76935069 | I38: 2842 | S38: 6.2935757
A39: Oregon | B39: 146 | C39: 10.652116 | D39: 6.4642383 | E39: 442949 | F39: 68523 | G39: 53174 | H39: 0.77600222 | I39: 3655 | S39: =ROUND(R39/1000000,1)&"M" -> 0M
A40: Pennsylvania | B40: 227 | C40: 15.044181 | D40: 5.7169079 | E40: 1807692 | F40: 316201 | G40: 260120 | H40: 0.82264129 | I40: 13951 | S40: =ROUND(R40/1000000,1)&".0M" -> 0.0M
...
